Workbook
Name Excel_BuiltIn_Print_Area_1: #REF!
Name Excel_BuiltIn_Print_Area_1: #REF!
Name Excel_BuiltIn_Print_Area_2: #REF!
Name Excel_BuiltIn_Print_Area_2: #REF!
Name Excel_BuiltIn_Print_Titles_1: #REF!
Name Excel_BuiltIn_Print_Titles_1: #REF!
Name Print_Titles: РДДС!$A:$B,РДДС!$2:$5

Sheet Вводные данные
B2: Вводные данные
A3: № | B3: Показатель | C3: 1 год | D3: 2 год | E3: 3 год
A4: 1 | B4: Инфляция | C4: 0 | D4: 0.15 | E4: 0.15
A5: 2 | B5: Потери при сбыте готовой продукции/ реализации товара | C5: 0 | D5: 0 | E5: 0
A6: 3 | B6: Размер обязательных взносов за ИП | C6: 53658 | D6: 57390 | E6: 61154
B8: Сезонность продаж
A9: № | B9: Месяц - начало продаж | C9: 45809 | D9: =EDATE(C9,1) -> 45839 | E9: =EDATE(D9,1) -> 45870 | F9: =EDATE(E9,1) -> 45901 | G9: =EDATE(F9,1) -> 45931 | H9: =EDATE(G9,1) -> 45962 | I9: =EDATE(H9,1) -> 45992 | J9: =EDATE(I9,1) -> 46023 | K9: =EDATE(J9,1) -> 46054 | ... N9: =EDATE(M9,1) -> 46143
A10: 1 | B10: Показатель | C10: 1 | D10: 0.9 | E10: 0.7 | F10: 0.7 | G10: 0.65 | H10: 0.65 | I10: 0.85 | J10: 0.65 | K10: 0.75 | L10: 0.7 | M10: 0.8 | N10: 0.9
B12: *Примечание: в шапке таблицы "Сезонность продаж" самостоятельно прописать месяц и год начала продаж в первом столбце. Во всем документе будет произведено автоматическое обновление дат!!!
B13: Месяц начала продаж должен идти после завершение всех этапов проекта!!!

Sheet РДДС
D2: Расчет движения денежных средств
A4: Код | B4: Наименование статьи | C4: Инвестиционный месяц | D4: 1 год | P4: Итого за 1 год | Q4: 2 год | AC4: Итого за 2 год | AD4: 3 год | AP4: Итого за 3 год | AQ4: Итого по проекту
D5: ='Вводные данные'!C9 -> 45809 | E5: ='Вводные данные'!D9 -> 45839 | F5: ='Вводные данные'!E9 -> 45870 | G5: ='Вводные данные'!F9 -> 45901 | H5: ='Вводные данные'!G9 -> 45931 | I5: ='Вводные данные'!H9 -> 45962 | J5: ='Вводные данные'!I9 -> 45992 | K5: ='Вводные данные'!J9 -> 46023 | ... O5: ='Вводные данные'!N9 -> 46143 | Q5: =EDATE(O5,1) -> 46174 | R5: =EDATE(Q5,1) -> 46204 | S5: =EDATE(R5,1) -> 46235 | T5: =EDATE(S5,1) -> 46266 | U5: =EDATE(T5,1) -> 46296 | V5: =EDATE(U5,1) -> 46327 | W5: =EDATE(V5,1) -> 46357 | X5: =EDATE(W5,1) -> 46388 | Y5: =EDATE(X5,1) -> 46419 | ... AB5: =EDATE(AA5,1) -> 46508 | AD5: =EDATE(AB5,1) -> 46539 | AE5: =EDATE(AD5,1) -> 46569 | AF5: =EDATE(AE5,1) -> 46600 | AG5: =EDATE(AF5,1) -> 46631 | AH5: =EDATE(AG5,1) -> 46661 | AI5: =EDATE(AH5,1) -> 46692 | AJ5: =EDATE(AI5,1) -> 46722 | AK5: =EDATE(AJ5,1) -> 46753 | AL5: =EDATE(AK5,1) -> 46784 | ... AO5: =EDATE(AN5,1) -> 46874
A6: 1 | B6: Доходы | D6: =Продажи!B31 -> 324000 | E6: =Продажи!C31 -> 79000 | F6: =Продажи!D31 -> 709000 | G6: =Продажи!E31 -> 264000 | H6: =Продажи!F31 -> 564000 | I6: =Продажи!G31 -> 714000 | J6: =Продажи!H31 -> 764000 | K6: =Продажи!I31 -> 791000 | ... O6: =Продажи!M31 -> 1191000 | P6: =SUM(D6:O6) -> 8458000 | Q6: =Продажи!O31 -> 1899800 | R6: =Продажи!P31 -> 2354050 | S6: =Продажи!Q31 -> 2256300 | T6: =Продажи!R31 -> 3042516.7 | U6: =Продажи!S31 -> 2657841.7 | V6: =Продажи!T31 -> 3132216.7 | W6: =Продажи!U31 -> 3068391.7 | X6: =Продажи!V31 -> 3850966.7 | ... AB6: =Продажи!Z31 -> 4636416.7 | AC6: =SUM(Q6:AB6) -> 38144350 | AD6: =Продажи!AB31 -> 5135267.5 | AE6: =Продажи!AC31 -> 5442087.5 | AF6: =Продажи!AD31 -> 5032112.5 | AG6: =Продажи!AE31 -> 5994892.5 | AH6: =Продажи!AF31 -> 5628560 | AI6: =Продажи!AG31 -> 6562245 | AJ6: =Продажи!AH31 -> 6280552.5 | AK6: =Продажи!AI31 -> 7216882.5 | ... AO6: =Продажи!AM31 -> 8356877.5 | AP6: =SUM(AD6:AO6) -> 77633395 | AQ6: =P6+AC6+AP6 -> 1.2423574e+08
A7: 2 | B7: Фонд оплаты труда (трудовые договора) | D7: =Персонал!B46 -> 520000 | E7: =Персонал!C46 -> 520000 | F7: =Персонал!D46 -> 520000 | G7: =Персонал!E46 -> 520000 | H7: =Персонал!F46 -> 520000 | I7: =Персонал!G46 -> 520000 | J7: =Персонал!H46 -> 520000 | K7: =Персонал!I46 -> 520000 | ... O7: =Персонал!M46 -> 520000 | P7: =SUM(D7:O7) -> 6240000 | Q7: =Персонал!O46 -> 1058000 | R7: =Персонал!P46 -> 1058000 | S7: =Персонал!Q46 -> 1058000 | T7: =Персонал!R46 -> 1058000 | U7: =Персонал!S46 -> 1058000 | V7: =Персонал!T46 -> 1058000 | W7: =Персонал!U46 -> 1058000 | X7: =Персонал!V46 -> 1058000 | ... AB7: =Персонал!Z46 -> 1058000 | AC7: =SUM(Q7:AB7) -> 12696000 | AD7: =Персонал!AB46 -> 1216700 | AE7: =Персонал!AC46 -> 1216700 | AF7: =Персонал!AD46 -> 1216700 | AG7: =Персонал!AE46 -> 1216700 | AH7: =Персонал!AF46 -> 1216700 | AI7: =Персонал!AG46 -> 1216700 | AJ7: =Персонал!AH46 -> 1216700 | AK7: =Персонал!AI46 -> 1216700 | ... AO7: =Персонал!AM46 -> 1216700 | AP7: =SUM(AD7:AO7) -> 14600400 | AQ7: =P7+AC7+AP7 -> 33536400
A8: 2.1 | B8: НДФЛ (ФОТ 13%) | D8: =D7*13% -> 67600 | E8: =E7*13% -> 67600 | F8: =F7*13% -> 67600 | G8: =G7*13% -> 67600 | H8: =H7*13% -> 67600 | I8: =I7*13% -> 67600 | J8: =J7*13% -> 67600 | K8: =K7*13% -> 67600 | ... O8: =O7*13% -> 67600 | P8: =SUM(D8:O8) -> 811200 | Q8: =Q7*13% -> 137540 | R8: =R7*13% -> 137540 | S8: =S7*13% -> 137540 | T8: =T7*13% -> 137540 | U8: =U7*13% -> 137540 | V8: =V7*13% -> 137540 | W8: =W7*13% -> 137540 | X8: =X7*13% -> 137540 | ... AB8: =AB7*13% -> 137540 | AC8: =SUM(Q8:AB8) -> 1650480 | AD8: =AD7*13% -> 158171 | AE8: =AE7*13% -> 158171 | AF8: =AF7*13% -> 158171 | AG8: =AG7*13% -> 158171 | AH8: =AH7*13% -> 158171 | AI8: =AI7*13% -> 158171 | AJ8: =AJ7*13% -> 158171 | AK8: =AK7*13% -> 158171 | ... AO8: =AO7*13% -> 158171 | AP8: =SUM(AD8:AO8) -> 1898052 | AQ8: =P8+AC8+AP8 -> 4359732
A9: 3 | B9: Взносы (ФОТ) | D9: =SUM(D10:D12) -> 157040 | E9: =SUM(E10:E12) -> 157040 | F9: =SUM(F10:F12) -> 157040 | G9: =SUM(G10:G12) -> 157040 | H9: =SUM(H10:H12) -> 157040 | I9: =SUM(I10:I12) -> 157040 | J9: =SUM(J10:J12) -> 157040 | K9: =SUM(K10:K12) -> 157040 | ... O9: =SUM(O10:O12) -> 157040 | P9: =SUM(D9:O9) -> 1884480 | Q9: =SUM(Q10:Q12) -> 319516 | R9: =SUM(R10:R12) -> 319516 | S9: =SUM(S10:S12) -> 319516 | T9: =SUM(T10:T12) -> 319516 | U9: =SUM(U10:U12) -> 319516 | V9: =SUM(V10:V12) -> 319516 | W9: =SUM(W10:W12) -> 319516 | X9: =SUM(X10:X12) -> 319516 | ... AB9: =SUM(AB10:AB12) -> 319516 | AC9: =SUM(Q9:AB9) -> 3834192 | AD9: =SUM(AD10:AD12) -> 367443.4 | AE9: =SUM(AE10:AE12) -> 367443.4 | AF9: =SUM(AF10:AF12) -> 367443.4 | AG9: =SUM(AG10:AG12) -> 367443.4 | AH9: =SUM(AH10:AH12) -> 367443.4 | AI9: =SUM(AI10:AI12) -> 367443.4 | AJ9: =SUM(AJ10:AJ12) -> 367443.4 | AK9: =SUM(AK10:AK12) -> 367443.4 | ... AO9: =SUM(AO10:AO12) -> 367443.4 | AP9: =SUM(AD9:AO9) -> 4409320.8 | AQ9: =P9+AC9+AP9 -> 10127993
A10: 3.1 | B10: Пенсионный фонд (ФОТ 22%) | D10: =D7*22% -> 114400 | E10: =E7*22% -> 114400 | F10: =F7*22% -> 114400 | G10: =G7*22% -> 114400 | H10: =H7*22% -> 114400 | I10: =I7*22% -> 114400 | J10: =J7*22% -> 114400 | K10: =K7*22% -> 114400 | ... O10: =O7*22% -> 114400 | P10: =SUM(D10:O10) -> 1372800 | Q10: =Q7*22% -> 232760 | R10: =R7*22% -> 232760 | S10: =S7*22% -> 232760 | T10: =T7*22% -> 232760 | U10: =U7*22% -> 232760 | V10: =V7*22% -> 232760 | W10: =W7*22% -> 232760 | X10: =X7*22% -> 232760 | ... AB10: =AB7*22% -> 232760 | AC10: =SUM(Q10:AB10) -> 2793120 | AD10: =AD7*22% -> 267674 | AE10: =AE7*22% -> 267674 | AF10: =AF7*22% -> 267674 | AG10: =AG7*22% -> 267674 | AH10: =AH7*22% -> 267674 | AI10: =AI7*22% -> 267674 | AJ10: =AJ7*22% -> 267674 | AK10: =AK7*22% -> 267674 | ... AO10: =AO7*22% -> 267674 | AP10: =SUM(AD10:AO10) -> 3212088 | AQ10: =P10+AC10+AP10 -> 7378008
A11: 3.2 | B11: ФФОМС, ТФОМС (ФОТ 5,1%) | D11: =D7*5.1% -> 26520 | E11: =E7*5.1% -> 26520 | F11: =F7*5.1% -> 26520 | G11: =G7*5.1% -> 26520 | H11: =H7*5.1% -> 26520 | I11: =I7*5.1% -> 26520 | J11: =J7*5.1% -> 26520 | K11: =K7*5.1% -> 26520 | ... O11: =O7*5.1% -> 26520 | P11: =SUM(D11:O11) -> 318240 | Q11: =Q7*5.1% -> 53958 | R11: =R7*5.1% -> 53958 | S11: =S7*5.1% -> 53958 | T11: =T7*5.1% -> 53958 | U11: =U7*5.1% -> 53958 | V11: =V7*5.1% -> 53958 | W11: =W7*5.1% -> 53958 | X11: =X7*5.1% -> 53958 | ... AB11: =AB7*5.1% -> 53958 | AC11: =SUM(Q11:AB11) -> 647496 | AD11: =AD7*5.1% -> 62051.7 | AE11: =AE7*5.1% -> 62051.7 | AF11: =AF7*5.1% -> 62051.7 | AG11: =AG7*5.1% -> 62051.7 | AH11: =AH7*5.1% -> 62051.7 | AI11: =AI7*5.1% -> 62051.7 | AJ11: =AJ7*5.1% -> 62051.7 | AK11: =AK7*5.1% -> 62051.7 | ... AO11: =AO7*5.1% -> 62051.7 | AP11: =SUM(AD11:AO11) -> 744620.4 | AQ11: =P11+AC11+AP11 -> 1710356.4
A12: 3.3 | B12: ФСС (ФОТ 0,2%+2,9%) | D12: =D7*3.1% -> 16120 | E12: =E7*3.1% -> 16120 | F12: =F7*3.1% -> 16120 | G12: =G7*3.1% -> 16120 | H12: =H7*3.1% -> 16120 | I12: =I7*3.1% -> 16120 | J12: =J7*3.1% -> 16120 | K12: =K7*3.1% -> 16120 | ... O12: =O7*3.1% -> 16120 | P12: =SUM(D12:O12) -> 193440 | Q12: =Q7*3.1% -> 32798 | R12: =R7*3.1% -> 32798 | S12: =S7*3.1% -> 32798 | T12: =T7*3.1% -> 32798 | U12: =U7*3.1% -> 32798 | V12: =V7*3.1% -> 32798 | W12: =W7*3.1% -> 32798 | X12: =X7*3.1% -> 32798 | ... AB12: =AB7*3.1% -> 32798 | AC12: =SUM(Q12:AB12) -> 393576 | AD12: =AD7*3.1% -> 37717.7 | AE12: =AE7*3.1% -> 37717.7 | AF12: =AF7*3.1% -> 37717.7 | AG12: =AG7*3.1% -> 37717.7 | AH12: =AH7*3.1% -> 37717.7 | AI12: =AI7*3.1% -> 37717.7 | AJ12: =AJ7*3.1% -> 37717.7 | AK12: =AK7*3.1% -> 37717.7 | ... AO12: =AO7*3.1% -> 37717.7 | AP12: =SUM(AD12:AO12) -> 452612.4 | AQ12: =P12+AC12+AP12 -> 1039628.4
A13: 4 | B13: Cдельная оплата труда | D13: ='Сдельная оплата труда'!C266 -> 300 | E13: ='Сдельная оплата труда'!D266 -> 200 | F13: ='Сдельная оплата труда'!E266 -> 500 | G13: ='Сдельная оплата труда'!F266 -> 600 | H13: ='Сдельная оплата труда'!G266 -> 800 | I13: ='Сдельная оплата труда'!H266 -> 1100 | J13: ='Сдельная оплата труда'!I266 -> 1300 | K13: ='Сдельная оплата труда'!J266 -> 1400 | ... O13: ='Сдельная оплата труда'!N266 -> 2400 | P13: =SUM(D13:O13) -> 14600 | Q13: ='Сдельная оплата труда'!P266 -> 4050 | R13: ='Сдельная оплата труда'!Q266 -> 4650 | S13: ='Сдельная оплата труда'!R266 -> 5250 | T13: ='Сдельная оплата труда'!S266 -> 6050 | U13: ='Сдельная оплата труда'!T266 -> 6575 | V13: ='Сдельная оплата труда'!U266 -> 7250 | W13: ='Сдельная оплата труда'!V266 -> 7775 | X13: ='Сдельная оплата труда'!W266 -> 8600 | ... AB13: ='Сдельная оплата труда'!AA266 -> 11150 | AC13: =SUM(Q13:AB13) -> 90600 | AD13: ='Сдельная оплата труда'!AC266 -> 1200 | AE13: ='Сдельная оплата труда'!AD266 -> 1200 | AF13: ='Сдельная оплата труда'!AE266 -> 1200 | AG13: ='Сдельная оплата труда'!AF266 -> 1200 | AH13: ='Сдельная оплата труда'!AG266 -> 1200 | AI13: ='Сдельная оплата труда'!AH266 -> 1200 | AJ13: ='Сдельная оплата труда'!AI266 -> 1400 | AK13: ='Сдельная оплата труда'!AJ266 -> 1400 | ... AO13: ='Сдельная оплата труда'!AN266 -> 1400 | AP13: =SUM(AD13:AO13) -> 15600 | AQ13: =P13+AC13+AP13 -> 120800
A14: 4.1 | B14: НДФЛ (Сдельная оплата труда 13%) | D14: =D13*13% -> 39 | E14: =E13*13% -> 26 | F14: =F13*13% -> 65 | G14: =G13*13% -> 78 | H14: =H13*13% -> 104 | I14: =I13*13% -> 143 | J14: =J13*13% -> 169 | K14: =K13*13% -> 182 | ... O14: =O13*13% -> 312 | P14: =SUM(D14:O14) -> 1898 | Q14: =Q13*13% -> 526.5 | R14: =R13*13% -> 604.5 | S14: =S13*13% -> 682.5 | T14: =T13*13% -> 786.5 | U14: =U13*13% -> 854.75 | V14: =V13*13% -> 942.5 | W14: =W13*13% -> 1010.75 | X14: =X13*13% -> 1118 | ... AB14: =AB13*13% -> 1449.5 | AC14: =SUM(Q14:AB14) -> 11778 | AD14: =AD13*13% -> 156 | AE14: =AE13*13% -> 156 | AF14: =AF13*13% -> 156 | AG14: =AG13*13% -> 156 | AH14: =AH13*13% -> 156 | AI14: =AI13*13% -> 156 | AJ14: =AJ13*13% -> 182 | AK14: =AK13*13% -> 182 | ... AO14: =AO13*13% -> 182 | AP14: =SUM(AD14:AO14) -> 2028 | AQ14: =P14+AC14+AP14 -> 15704
A15: 5 | B15: Взносы (сдельная оплата труда) | D15: =SUM(D16:D18) -> 90.6 | E15: =SUM(E16:E18) -> 60.4 | F15: =SUM(F16:F18) -> 151 | G15: =SUM(G16:G18) -> 181.2 | H15: =SUM(H16:H18) -> 241.6 | I15: =SUM(I16:I18) -> 332.2 | J15: =SUM(J16:J18) -> 392.6 | K15: =SUM(K16:K18) -> 422.8 | ... O15: =SUM(O16:O18) -> 724.8 | P15: =SUM(D15:O15) -> 4409.2 | Q15: =SUM(Q16:Q18) -> 1223.1 | R15: =SUM(R16:R18) -> 1404.3 | S15: =SUM(S16:S18) -> 1585.5 | T15: =SUM(T16:T18) -> 1827.1 | U15: =SUM(U16:U18) -> 1985.65 | V15: =SUM(V16:V18) -> 2189.5 | W15: =SUM(W16:W18) -> 2348.05 | X15: =SUM(X16:X18) -> 2597.2 | ... AB15: =SUM(AB16:AB18) -> 3367.3 | AC15: =SUM(Q15:AB15) -> 27361.2 | AD15: =SUM(AD16:AD18) -> 362.4 | AE15: =SUM(AE16:AE18) -> 362.4 | AF15: =SUM(AF16:AF18) -> 362.4 | AG15: =SUM(AG16:AG18) -> 362.4 | AH15: =SUM(AH16:AH18) -> 362.4 | AI15: =SUM(AI16:AI18) -> 362.4 | AJ15: =SUM(AJ16:AJ18) -> 422.8 | AK15: =SUM(AK16:AK18) -> 422.8 | ... AO15: =SUM(AO16:AO18) -> 422.8 | AP15: =SUM(AD15:AO15) -> 4711.2 | AQ15: =P15+AC15+AP15 -> 36481.6
A16: 5.1 | B16: Пенсионный фонд (22%) | D16: =D13*22% -> 66 | E16: =E13*22% -> 44 | F16: =F13*22% -> 110 | G16: =G13*22% -> 132 | H16: =H13*22% -> 176 | I16: =I13*22% -> 242 | J16: =J13*22% -> 286 | K16: =K13*22% -> 308 | ... O16: =O13*22% -> 528 | P16: =SUM(D16:O16) -> 3212 | Q16: =Q13*22% -> 891 | R16: =R13*22% -> 1023 | S16: =S13*22% -> 1155 | T16: =T13*22% -> 1331 | U16: =U13*22% -> 1446.5 | V16: =V13*22% -> 1595 | W16: =W13*22% -> 1710.5 | X16: =X13*22% -> 1892 | ... AB16: =AB13*22% -> 2453 | AC16: =SUM(Q16:AB16) -> 19932 | AD16: =AD13*22% -> 264 | AE16: =AE13*22% -> 264 | AF16: =AF13*22% -> 264 | AG16: =AG13*22% -> 264 | AH16: =AH13*22% -> 264 | AI16: =AI13*22% -> 264 | AJ16: =AJ13*22% -> 308 | AK16: =AK13*22% -> 308 | ... AO16: =AO13*22% -> 308 | AP16: =SUM(AD16:AO16) -> 3432 | AQ16: =P16+AC16+AP16 -> 26576
A17: 5.2 | B17: ФФОМС, ТФОМС (5,1%) | D17: =D13*5.1% -> 15.3 | E17: =E13*5.1% -> 10.2 | F17: =F13*5.1% -> 25.5 | G17: =G13*5.1% -> 30.6 | H17: =H13*5.1% -> 40.8 | I17: =I13*5.1% -> 56.1 | J17: =J13*5.1% -> 66.3 | K17: =K13*5.1% -> 71.4 | ... O17: =O13*5.1% -> 122.4 | P17: =SUM(D17:O17) -> 744.6 | Q17: =Q13*5.1% -> 206.55 | R17: =R13*5.1% -> 237.15 | S17: =S13*5.1% -> 267.75 | T17: =T13*5.1% -> 308.55 | U17: =U13*5.1% -> 335.325 | V17: =V13*5.1% -> 369.75 | W17: =W13*5.1% -> 396.525 | X17: =X13*5.1% -> 438.6 | ... AB17: =AB13*5.1% -> 568.65 | AC17: =SUM(Q17:AB17) -> 4620.6 | AD17: =AD13*5.1% -> 61.2 | AE17: =AE13*5.1% -> 61.2 | AF17: =AF13*5.1% -> 61.2 | AG17: =AG13*5.1% -> 61.2 | AH17: =AH13*5.1% -> 61.2 | AI17: =AI13*5.1% -> 61.2 | AJ17: =AJ13*5.1% -> 71.4 | AK17: =AK13*5.1% -> 71.4 | ... AO17: =AO13*5.1% -> 71.4 | AP17: =SUM(AD17:AO17) -> 795.6 | AQ17: =P17+AC17+AP17 -> 6160.8
A18: 5.3 | B18: ФСС (0,2%+2,9%) | D18: =D13*3.1% -> 9.3 | E18: =E13*3.1% -> 6.2 | F18: =F13*3.1% -> 15.5 | G18: =G13*3.1% -> 18.6 | H18: =H13*3.1% -> 24.8 | I18: =I13*3.1% -> 34.1 | J18: =J13*3.1% -> 40.3 | K18: =K13*3.1% -> 43.4 | ... O18: =O13*3.1% -> 74.4 | P18: =SUM(D18:O18) -> 452.6 | Q18: =Q13*3.1% -> 125.55 | R18: =R13*3.1% -> 144.15 | S18: =S13*3.1% -> 162.75 | T18: =T13*3.1% -> 187.55 | U18: =U13*3.1% -> 203.825 | V18: =V13*3.1% -> 224.75 | W18: =W13*3.1% -> 241.025 | X18: =X13*3.1% -> 266.6 | ... AB18: =AB13*3.1% -> 345.65 | AC18: =SUM(Q18:AB18) -> 2808.6 | AD18: =AD13*3.1% -> 37.2 | AE18: =AE13*3.1% -> 37.2 | AF18: =AF13*3.1% -> 37.2 | AG18: =AG13*3.1% -> 37.2 | AH18: =AH13*3.1% -> 37.2 | AI18: =AI13*3.1% -> 37.2 | AJ18: =AJ13*3.1% -> 43.4 | AK18: =AK13*3.1% -> 43.4 | ... AO18: =AO13*3.1% -> 43.4 | AP18: =SUM(AD18:AO18) -> 483.6 | AQ18: =P18+AC18+AP18 -> 3744.8
A19: 6 | B19: Налог | D19: =SUM(D20:D21) -> 30709.833 | E19: =SUM(E20:E21) -> 16009.833 | F19: =SUM(F20:F21) -> 53809.833 | G19: =SUM(G20:G21) -> 27109.833 | H19: =SUM(H20:H21) -> 45109.833 | I19: =SUM(I20:I21) -> 54109.833 | J19: =SUM(J20:J21) -> 57109.833 | K19: =SUM(K20:K21) -> 58729.833 | ... O19: =SUM(O20:O21) -> 82729.833 | P19: =SUM(D19:O19) -> 642718 | Q19: =SUM(Q20:Q21) -> 150307.46 | R19: =SUM(R20:R21) -> 177562.46 | S19: =SUM(S20:S21) -> 171697.46 | T19: =SUM(T20:T21) -> 218870.46 | U19: =SUM(U20:U21) -> 195789.96 | V19: =SUM(V20:V21) -> 224252.46 | W19: =SUM(W20:W21) -> 220422.96 | X19: =SUM(X20:X21) -> 267377.46 | ... AB19: =SUM(AB20:AB21) -> 314504.46 | AC19: =SUM(Q19:AB19) -> 2724494.5 | AD19: =SUM(AD20:AD21) -> 377656.71 | AE19: =SUM(AE20:AE21) -> 396065.91 | AF19: =SUM(AF20:AF21) -> 371467.41 | AG19: =SUM(AG20:AG21) -> 429234.21 | AH19: =SUM(AH20:AH21) -> 407254.26 | AI19: =SUM(AI20:AI21) -> 463275.36 | AJ19: =SUM(AJ20:AJ21) -> 446373.81 | AK19: =SUM(AK20:AK21) -> 502553.61 | ... AO19: =SUM(AO20:AO21) -> 570953.31 | AP19: =SUM(AD19:AO19) -> 5492491.7 | AQ19: =P19+AC19+AP19 -> 8859704.1
A20: 6.1 | B20: Налог УСН 6% (например) | D20: =D6*6% -> 19440 | E20: =E6*6% -> 4740 | F20: =F6*6% -> 42540 | G20: =G6*6% -> 15840 | H20: =H6*6% -> 33840 | I20: =I6*6% -> 42840 | J20: =J6*6% -> 45840 | K20: =K6*6% -> 47460 | ... O20: =O6*6% -> 71460 | P20: =SUM(D20:O20) -> 507480 | Q20: =Q6*6% -> 113988 | R20: =R6*6% -> 141243 | S20: =S6*6% -> 135378 | T20: =T6*6% -> 182551 | U20: =U6*6% -> 159470.5 | V20: =V6*6% -> 187933 | W20: =W6*6% -> 184103.5 | X20: =X6*6% -> 231058 | ... AB20: =AB6*6% -> 278185 | AC20: =SUM(Q20:AB20) -> 2288661 | AD20: =AD6*6% -> 308116.05 | AE20: =AE6*6% -> 326525.25 | AF20: =AF6*6% -> 301926.75 | AG20: =AG6*6% -> 359693.55 | AH20: =AH6*6% -> 337713.6 | AI20: =AI6*6% -> 393734.7 | AJ20: =AJ6*6% -> 376833.15 | AK20: =AK6*6% -> 433012.95 | ... AO20: =AO6*6% -> 501412.65 | AP20: =SUM(AD20:AO20) -> 4658003.7 | AQ20: =P20+AC20+AP20 -> 7454144.7
A21: 6.2 | B21: Взнос ИП фиксированный | D21: ='Вводные данные'!$C$6/12+(($P$6-300000)*1%/12) -> 11269.833 | E21: ='Вводные данные'!$C$6/12+(($P$6-300000)*1%/12) -> 11269.833 | F21: ='Вводные данные'!$C$6/12+(($P$6-300000)*1%/12) -> 11269.833 | G21: ='Вводные данные'!$C$6/12+(($P$6-300000)*1%/12) -> 11269.833 | H21: ='Вводные данные'!$C$6/12+(($P$6-300000)*1%/12) -> 11269.833 | I21: ='Вводные данные'!$C$6/12+(($P$6-300000)*1%/12) -> 11269.833 | J21: ='Вводные данные'!$C$6/12+(($P$6-300000)*1%/12) -> 11269.833 | K21: ='Вводные данные'!$C$6/12+(($P$6-300000)*1%/12) -> 11269.833 | ... O21: ='Вводные данные'!$C$6/12+(($P$6-300000)*1%/12) -> 11269.833 | P21: =SUM(D21:O21) -> 135238 | Q21: =('Вводные данные'!$D$6/12+(($AC$6-300000)*1%/12)) -> 36319.458 | R21: =('Вводные данные'!$D$6/12+(($AC$6-300000)*1%/12)) -> 36319.458 | S21: =('Вводные данные'!$D$6/12+(($AC$6-300000)*1%/12)) -> 36319.458 | T21: =('Вводные данные'!$D$6/12+(($AC$6-300000)*1%/12)) -> 36319.458 | U21: =('Вводные данные'!$D$6/12+(($AC$6-300000)*1%/12)) -> 36319.458 | V21: =('Вводные данные'!$D$6/12+(($AC$6-300000)*1%/12)) -> 36319.458 | W21: =('Вводные данные'!$D$6/12+(($AC$6-300000)*1%/12)) -> 36319.458 | X21: =('Вводные данные'!$D$6/12+(($AC$6-300000)*1%/12)) -> 36319.458 | ... AB21: =('Вводные данные'!$D$6/12+(($AC$6-300000)*1%/12)) -> 36319.458 | AC21: =SUM(Q21:AB21) -> 435833.5 | AD21: =('Вводные данные'!$E$6/12+(($AP$6-300000)*1%/12)) -> 69540.663 | AE21: =('Вводные данные'!$E$6/12+(($AP$6-300000)*1%/12)) -> 69540.663 | AF21: =('Вводные данные'!$E$6/12+(($AP$6-300000)*1%/12)) -> 69540.663 | AG21: =('Вводные данные'!$E$6/12+(($AP$6-300000)*1%/12)) -> 69540.663 | AH21: =('Вводные данные'!$E$6/12+(($AP$6-300000)*1%/12)) -> 69540.663 | AI21: =('Вводные данные'!$E$6/12+(($AP$6-300000)*1%/12)) -> 69540.663 | AJ21: =('Вводные данные'!$E$6/12+(($AP$6-300000)*1%/12)) -> 69540.663 | AK21: =('Вводные данные'!$E$6/12+(($AP$6-300000)*1%/12)) -> 69540.663 | ... AO21: =('Вводные данные'!$E$6/12+(($AP$6-300000)*1%/12)) -> 69540.663 | AP21: =SUM(AD21:AO21) -> 834487.95 | AQ21: =P21+AC21+AP21 -> 1405559.4
A22: 7 | B22: Маркетинговые расходы | D22: =Маркетинг!B12 -> 61500 | E22: =Маркетинг!C12 -> 61500 | F22: =Маркетинг!D12 -> 61500 | G22: =Маркетинг!E12 -> 61500 | H22: =Маркетинг!F12 -> 61500 | I22: =Маркетинг!G12 -> 61500 | J22: =Маркетинг!H12 -> 61500 | K22: =Маркетинг!I12 -> 61500 | ... O22: =Маркетинг!M12 -> 61500 | P22: =SUM(D22:O22) -> 738000 | Q22: =Маркетинг!O12 -> 70725 | R22: =Маркетинг!P12 -> 70725 | S22: =Маркетинг!Q12 -> 70725 | T22: =Маркетинг!R12 -> 70725 | U22: =Маркетинг!S12 -> 70725 | V22: =Маркетинг!T12 -> 70725 | W22: =Маркетинг!U12 -> 70725 | X22: =Маркетинг!V12 -> 70725 | ... AB22: =Маркетинг!Z12 -> 70725 | AC22: =SUM(Q22:AB22) -> 848700 | AD22: =Маркетинг!AB12 -> 81333.75 | AE22: =Маркетинг!AC12 -> 81333.75 | AF22: =Маркетинг!AD12 -> 81333.75 | AG22: =Маркетинг!AE12 -> 81333.75 | AH22: =Маркетинг!AF12 -> 81333.75 | AI22: =Маркетинг!AG12 -> 81333.75 | AJ22: =Маркетинг!AH12 -> 81333.75 | AK22: =Маркетинг!AI12 -> 81333.75 | ... AO22: =Маркетинг!AM12 -> 81333.75 | AP22: =SUM(AD22:AO22) -> 976005 | AQ22: =P22+AC22+AP22 -> 2562705
A23: 8 | B23: Административно-хозяйственные и производственные расходы | D23: =SUM(D24:D39) -> 142800 | E23: =SUM(E24:E39) -> 97400 | F23: =SUM(F24:F39) -> 202100 | G23: =SUM(G24:G39) -> 117000 | H23: =SUM(H24:H39) -> 167600 | I23: =SUM(I24:I39) -> 183900 | J23: =SUM(J24:J39) -> 189500 | K23: =SUM(K24:K39) -> 205400 | ... O23: =SUM(O24:O39) -> 249200 | P23: =SUM(D23:O23) -> 2246000 | Q23: =SUM(Q24:Q39) -> 367655 | R23: =SUM(R24:R39) -> 438610 | S23: =SUM(S24:S39) -> 407905 | T23: =SUM(T24:T39) -> 550275 | U23: =SUM(U24:U39) -> 468510 | V23: =SUM(V24:V39) -> 541535 | W23: =SUM(W24:W39) -> 514395 | X23: =SUM(X24:X39) -> 656075 | ... AB23: =SUM(AB24:AB39) -> 760380 | AC23: =SUM(Q23:AB23) -> 6546835 | AD23: =SUM(AD24:AD39) -> 910673.5 | AE23: =SUM(AE24:AE39) -> 963705.75 | AF23: =SUM(AF24:AF39) -> 874040.25 | AG23: =SUM(AG24:AG39) -> 1039969.9 | AH23: =SUM(AH24:AH39) -> 964256.79 | AI23: =SUM(AI24:AI39) -> 1125403.4 | AJ23: =SUM(AJ24:AJ39) -> 1057757.5 | AK23: =SUM(AK24:AK39) -> 1217449.4 | ... AO23: =SUM(AO24:AO39) -> 1385406.9 | AP23: =SUM(AD23:AO23) -> 13199476 | AQ23: =P23+AC23+AP23 -> 21992311
A24: 8.1 | B24: Производственные расходы | D24: ='Переменные затраты'!H126 -> 53800 | E24: ='Переменные затраты'!I126 -> 8400 | F24: ='Переменные затраты'!J126 -> 113100 | G24: ='Переменные затраты'!K126 -> 28000 | H24: ='Переменные затраты'!L126 -> 78600 | I24: ='Переменные затраты'!M126 -> 94900 | J24: ='Переменные затраты'!N126 -> 100500 | K24: ='Переменные затраты'!O126 -> 116400 | ... O24: ='Переменные затраты'!S126 -> 160200 | P24: =SUM(D24:O24) -> 1178000 | Q24: ='Переменные затраты'!U126 -> 265305 | R24: ='Переменные затраты'!V126 -> 336260 | S24: ='Переменные затраты'!W126 -> 305555 | T24: ='Переменные затраты'!X126 -> 447925 | U24: ='Переменные затраты'!Y126 -> 366160 | V24: ='Переменные затраты'!Z126 -> 439185 | W24: ='Переменные затраты'!AA126 -> 412045 | X24: ='Переменные затраты'!AB126 -> 553725 | ... AB24: ='Переменные затраты'!AF126 -> 658030 | AC24: =SUM(Q24:AB24) -> 5318635 | AD24: ='Переменные затраты'!AH126 -> 792971 | AE24: ='Переменные затраты'!AI126 -> 846003.25 | AF24: ='Переменные затраты'!AJ126 -> 756337.75 | AG24: ='Переменные затраты'!AK126 -> 922267.42 | AH24: ='Переменные затраты'!AL126 -> 846554.29 | AI24: ='Переменные затраты'!AM126 -> 1007700.9 | AJ24: ='Переменные затраты'!AN126 -> 940055.04 | AK24: ='Переменные затраты'!AO126 -> 1099746.9 | ... AO24: ='Переменные затраты'!AS126 -> 1267704.4 | AP24: =SUM(AD24:AO24) -> 11787046 | AQ24: =P24+AC24+AP24 -> 18283681
A25: 8.2 | B25: ='Постоянные затраты'!A5 -> Бухгалтерия | D25: ='Постоянные затраты'!B5 -> 10000 | E25: ='Постоянные затраты'!C5 -> 10000 | F25: ='Постоянные затраты'!D5 -> 10000 | G25: ='Постоянные затраты'!E5 -> 10000 | H25: ='Постоянные затраты'!F5 -> 10000 | I25: ='Постоянные затраты'!G5 -> 10000 | J25: ='Постоянные затраты'!H5 -> 10000 | K25: ='Постоянные затраты'!I5 -> 10000 | ... O25: ='Постоянные затраты'!M5 -> 10000 | P25: =SUM(D25:O25) -> 120000 | Q25: ='Постоянные затраты'!O5 -> 11500 | R25: ='Постоянные затраты'!P5 -> 11500 | S25: ='Постоянные затраты'!Q5 -> 11500 | T25: ='Постоянные затраты'!R5 -> 11500 | U25: ='Постоянные затраты'!S5 -> 11500 | V25: ='Постоянные затраты'!T5 -> 11500 | W25: ='Постоянные затраты'!U5 -> 11500 | X25: ='Постоянные затраты'!V5 -> 11500 | ... AB25: ='Постоянные затраты'!Z5 -> 11500 | AC25: =SUM(Q25:AB25) -> 138000 | AD25: ='Постоянные затраты'!AB5 -> 13225 | AE25: ='Постоянные затраты'!AC5 -> 13225 | AF25: ='Постоянные затраты'!AD5 -> 13225 | AG25: ='Постоянные затраты'!AE5 -> 13225 | AH25: ='Постоянные затраты'!AF5 -> 13225 | AI25: ='Постоянные затраты'!AG5 -> 13225 | AJ25: ='Постоянные затраты'!AH5 -> 13225 | AK25: ='Постоянные затраты'!AI5 -> 13225 | ... AO25: ='Постоянные затраты'!AM5 -> 13225 | AP25: =SUM(AD25:AO25) -> 158700 | AQ25: =P25+AC25+AP25 -> 416700
A26: 8.3 | B26: ='Постоянные затраты'!A6 -> Юридические | D26: ='Постоянные затраты'!B6 -> 10000 | E26: ='Постоянные затраты'!C6 -> 10000 | F26: ='Постоянные затраты'!D6 -> 10000 | G26: ='Постоянные затраты'!E6 -> 10000 | H26: ='Постоянные затраты'!F6 -> 10000 | I26: ='Постоянные затраты'!G6 -> 10000 | J26: ='Постоянные затраты'!H6 -> 10000 | K26: ='Постоянные затраты'!I6 -> 10000 | ... O26: ='Постоянные затраты'!M6 -> 10000 | P26: =SUM(D26:O26) -> 120000 | Q26: ='Постоянные затраты'!O6 -> 11500 | R26: ='Постоянные затраты'!P6 -> 11500 | S26: ='Постоянные затраты'!Q6 -> 11500 | T26: ='Постоянные затраты'!R6 -> 11500 | U26: ='Постоянные затраты'!S6 -> 11500 | V26: ='Постоянные затраты'!T6 -> 11500 | W26: ='Постоянные затраты'!U6 -> 11500 | X26: ='Постоянные затраты'!V6 -> 11500 | ... AB26: ='Постоянные затраты'!Z6 -> 11500 | AC26: =SUM(Q26:AB26) -> 138000 | AD26: ='Постоянные затраты'!AB6 -> 13225 | AE26: ='Постоянные затраты'!AC6 -> 13225 | AF26: ='Постоянные затраты'!AD6 -> 13225 | AG26: ='Постоянные затраты'!AE6 -> 13225 | AH26: ='Постоянные затраты'!AF6 -> 13225 | AI26: ='Постоянные затраты'!AG6 -> 13225 | AJ26: ='Постоянные затраты'!AH6 -> 13225 | AK26: ='Постоянные затраты'!AI6 -> 13225 | ... AO26: ='Постоянные затраты'!AM6 -> 13225 | AP26: =SUM(AD26:AO26) -> 158700 | AQ26: =P26+AC26+AP26 -> 416700
A27: 8.4 | B27: ='Постоянные затраты'!A7 -> 0 | D27: ='Постоянные затраты'!B7 -> 0 | E27: ='Постоянные затраты'!C7 -> 0 | F27: ='Постоянные затраты'!D7 -> 0 | G27: ='Постоянные затраты'!E7 -> 0 | H27: ='Постоянные затраты'!F7 -> 0 | I27: ='Постоянные затраты'!G7 -> 0 | J27: ='Постоянные затраты'!H7 -> 0 | K27: ='Постоянные затраты'!I7 -> 0 | ... O27: ='Постоянные затраты'!M7 -> 0 | P27: =SUM(D27:O27) -> 0 | Q27: ='Постоянные затраты'!O7 -> 0 | R27: ='Постоянные затраты'!P7 -> 0 | S27: ='Постоянные затраты'!Q7 -> 0 | T27: ='Постоянные затраты'!R7 -> 0 | U27: ='Постоянные затраты'!S7 -> 0 | V27: ='Постоянные затраты'!T7 -> 0 | W27: ='Постоянные затраты'!U7 -> 0 | X27: ='Постоянные затраты'!V7 -> 0 | ... AB27: ='Постоянные затраты'!Z7 -> 0 | AC27: =SUM(Q27:AB27) -> 0 | AD27: ='Постоянные затраты'!AB7 -> 0 | AE27: ='Постоянные затраты'!AC7 -> 0 | AF27: ='Постоянные затраты'!AD7 -> 0 | AG27: ='Постоянные затраты'!AE7 -> 0 | AH27: ='Постоянные затраты'!AF7 -> 0 | AI27: ='Постоянные затраты'!AG7 -> 0 | AJ27: ='Постоянные затраты'!AH7 -> 0 | AK27: ='Постоянные затраты'!AI7 -> 0 | ... AO27: ='Постоянные затраты'!AM7 -> 0 | AP27: =SUM(AD27:AO27) -> 0 | AQ27: =P27+AC27+AP27 -> 0
A28: 8.5 | B28: ='Постоянные затраты'!A8 -> Офис аренда | D28: ='Постоянные затраты'!B8 -> 30000 | E28: ='Постоянные затраты'!C8 -> 30000 | F28: ='Постоянные затраты'!D8 -> 30000 | G28: ='Постоянные затраты'!E8 -> 30000 | H28: ='Постоянные затраты'!F8 -> 30000 | I28: ='Постоянные затраты'!G8 -> 30000 | J28: ='Постоянные затраты'!H8 -> 30000 | K28: ='Постоянные затраты'!I8 -> 30000 | ... O28: ='Постоянные затраты'!M8 -> 30000 | P28: =SUM(D28:O28) -> 360000 | Q28: ='Постоянные затраты'!O8 -> 34500 | R28: ='Постоянные затраты'!P8 -> 34500 | S28: ='Постоянные затраты'!Q8 -> 34500 | T28: ='Постоянные затраты'!R8 -> 34500 | U28: ='Постоянные затраты'!S8 -> 34500 | V28: ='Постоянные затраты'!T8 -> 34500 | W28: ='Постоянные затраты'!U8 -> 34500 | X28: ='Постоянные затраты'!V8 -> 34500 | ... AB28: ='Постоянные затраты'!Z8 -> 34500 | AC28: =SUM(Q28:AB28) -> 414000 | AD28: ='Постоянные затраты'!AB8 -> 39675 | AE28: ='Постоянные затраты'!AC8 -> 39675 | AF28: ='Постоянные затраты'!AD8 -> 39675 | AG28: ='Постоянные затраты'!AE8 -> 39675 | AH28: ='Постоянные затраты'!AF8 -> 39675 | AI28: ='Постоянные затраты'!AG8 -> 39675 | AJ28: ='Постоянные затраты'!AH8 -> 39675 | AK28: ='Постоянные затраты'!AI8 -> 39675 | ... AO28: ='Постоянные затраты'!AM8 -> 39675 | AP28: =SUM(AD28:AO28) -> 476100 | AQ28: =P28+AC28+AP28 -> 1250100
A29: 8.6 | B29: ='Постоянные затраты'!A9 -> Прочее (связь, интернет, канцелярия) | D29: ='Постоянные затраты'!B9 -> 4000 | E29: ='Постоянные затраты'!C9 -> 4000 | F29: ='Постоянные затраты'!D9 -> 4000 | G29: ='Постоянные затраты'!E9 -> 4000 | H29: ='Постоянные затраты'!F9 -> 4000 | I29: ='Постоянные затраты'!G9 -> 4000 | J29: ='Постоянные затраты'!H9 -> 4000 | K29: ='Постоянные затраты'!I9 -> 4000 | ... O29: ='Постоянные затраты'!M9 -> 4000 | P29: =SUM(D29:O29) -> 48000 | Q29: ='Постоянные затраты'!O9 -> 4600 | R29: ='Постоянные затраты'!P9 -> 4600 | S29: ='Постоянные затраты'!Q9 -> 4600 | T29: ='Постоянные затраты'!R9 -> 4600 | U29: ='Постоянные затраты'!S9 -> 4600 | V29: ='Постоянные затраты'!T9 -> 4600 | W29: ='Постоянные затраты'!U9 -> 4600 | X29: ='Постоянные затраты'!V9 -> 4600 | ... AB29: ='Постоянные затраты'!Z9 -> 4600 | AC29: =SUM(Q29:AB29) -> 55200 | AD29: ='Постоянные затраты'!AB9 -> 5290 | AE29: ='Постоянные затраты'!AC9 -> 5290 | AF29: ='Постоянные затраты'!AD9 -> 5290 | AG29: ='Постоянные затраты'!AE9 -> 5290 | AH29: ='Постоянные затраты'!AF9 -> 5290 | AI29: ='Постоянные затраты'!AG9 -> 5290 | AJ29: ='Постоянные затраты'!AH9 -> 5290 | AK29: ='Постоянные затраты'!AI9 -> 5290 | ... AO29: ='Постоянные затраты'!AM9 -> 5290 | AP29: =SUM(AD29:AO29) -> 63480 | AQ29: =P29+AC29+AP29 -> 166680
A30: 8.7 | B30: ='Постоянные затраты'!A10 -> Хостинг и облака | D30: ='Постоянные затраты'!B10 -> 15000 | E30: ='Постоянные затраты'!C10 -> 15000 | F30: ='Постоянные затраты'!D10 -> 15000 | G30: ='Постоянные затраты'!E10 -> 15000 | H30: ='Постоянные затраты'!F10 -> 15000 | I30: ='Постоянные затраты'!G10 -> 15000 | J30: ='Постоянные затраты'!H10 -> 15000 | K30: ='Постоянные затраты'!I10 -> 15000 | ... O30: ='Постоянные затраты'!M10 -> 15000 | P30: =SUM(D30:O30) -> 180000 | Q30: ='Постоянные затраты'!O10 -> 17250 | R30: ='Постоянные затраты'!P10 -> 17250 | S30: ='Постоянные затраты'!Q10 -> 17250 | T30: ='Постоянные затраты'!R10 -> 17250 | U30: ='Постоянные затраты'!S10 -> 17250 | V30: ='Постоянные затраты'!T10 -> 17250 | W30: ='Постоянные затраты'!U10 -> 17250 | X30: ='Постоянные затраты'!V10 -> 17250 | ... AB30: ='Постоянные затраты'!Z10 -> 17250 | AC30: =SUM(Q30:AB30) -> 207000 | AD30: ='Постоянные затраты'!AB10 -> 19837.5 | AE30: ='Постоянные затраты'!AC10 -> 19837.5 | AF30: ='Постоянные затраты'!AD10 -> 19837.5 | AG30: ='Постоянные затраты'!AE10 -> 19837.5 | AH30: ='Постоянные затраты'!AF10 -> 19837.5 | AI30: ='Постоянные затраты'!AG10 -> 19837.5 | AJ30: ='Постоянные затраты'!AH10 -> 19837.5 | AK30: ='Постоянные затраты'!AI10 -> 19837.5 | ... AO30: ='Постоянные затраты'!AM10 -> 19837.5 | AP30: =SUM(AD30:AO30) -> 238050 | AQ30: =P30+AC30+AP30 -> 625050
A31: 8.8 | B31: ='Постоянные затраты'!A11 -> Домены, SSL, почта | D31: ='Постоянные затраты'!B11 -> 5000 | E31: ='Постоянные затраты'!C11 -> 5000 | F31: ='Постоянные затраты'!D11 -> 5000 | G31: ='Постоянные затраты'!E11 -> 5000 | H31: ='Постоянные затраты'!F11 -> 5000 | I31: ='Постоянные затраты'!G11 -> 5000 | J31: ='Постоянные затраты'!H11 -> 5000 | K31: ='Постоянные затраты'!I11 -> 5000 | ... O31: ='Постоянные затраты'!M11 -> 5000 | P31: =SUM(D31:O31) -> 60000 | Q31: ='Постоянные затраты'!O11 -> 5750 | R31: ='Постоянные затраты'!P11 -> 5750 | S31: ='Постоянные затраты'!Q11 -> 5750 | T31: ='Постоянные затраты'!R11 -> 5750 | U31: ='Постоянные затраты'!S11 -> 5750 | V31: ='Постоянные затраты'!T11 -> 5750 | W31: ='Постоянные затраты'!U11 -> 5750 | X31: ='Постоянные затраты'!V11 -> 5750 | ... AB31: ='Постоянные затраты'!Z11 -> 5750 | AC31: =SUM(Q31:AB31) -> 69000 | AD31: ='Постоянные затраты'!AB11 -> 6612.5 | AE31: ='Постоянные затраты'!AC11 -> 6612.5 | AF31: ='Постоянные затраты'!AD11 -> 6612.5 | AG31: ='Постоянные затраты'!AE11 -> 6612.5 | AH31: ='Постоянные затраты'!AF11 -> 6612.5 | AI31: ='Постоянные затраты'!AG11 -> 6612.5 | AJ31: ='Постоянные затраты'!AH11 -> 6612.5 | AK31: ='Постоянные затраты'!AI11 -> 6612.5 | ... AO31: ='Постоянные затраты'!AM11 -> 6612.5 | AP31: =SUM(AD31:AO31) -> 79350 | AQ31: =P31+AC31+AP31 -> 208350
A32: 8.9 | B32: ='Постоянные затраты'!A12 -> SaaS-сервисы | D32: ='Постоянные затраты'!B12 -> 10000 | E32: ='Постоянные затраты'!C12 -> 10000 | F32: ='Постоянные затраты'!D12 -> 10000 | G32: ='Постоянные затраты'!E12 -> 10000 | H32: ='Постоянные затраты'!F12 -> 10000 | I32: ='Постоянные затраты'!G12 -> 10000 | J32: ='Постоянные затраты'!H12 -> 10000 | K32: ='Постоянные затраты'!I12 -> 10000 | ... O32: ='Постоянные затраты'!M12 -> 10000 | P32: =SUM(D32:O32) -> 120000 | Q32: ='Постоянные затраты'!O12 -> 11500 | R32: ='Постоянные затраты'!P12 -> 11500 | S32: ='Постоянные затраты'!Q12 -> 11500 | T32: ='Постоянные затраты'!R12 -> 11500 | U32: ='Постоянные затраты'!S12 -> 11500 | V32: ='Постоянные затраты'!T12 -> 11500 | W32: ='Постоянные затраты'!U12 -> 11500 | X32: ='Постоянные затраты'!V12 -> 11500 | ... AB32: ='Постоянные затраты'!Z12 -> 11500 | AC32: =SUM(Q32:AB32) -> 138000 | AD32: ='Постоянные затраты'!AB12 -> 13225 | AE32: ='Постоянные затраты'!AC12 -> 13225 | AF32: ='Постоянные затраты'!AD12 -> 13225 | AG32: ='Постоянные затраты'!AE12 -> 13225 | AH32: ='Постоянные затраты'!AF12 -> 13225 | AI32: ='Постоянные затраты'!AG12 -> 13225 | AJ32: ='Постоянные затраты'!AH12 -> 13225 | AK32: ='Постоянные затраты'!AI12 -> 13225 | ... AO32: ='Постоянные затраты'!AM12 -> 13225 | AP32: =SUM(AD32:AO32) -> 158700 | AQ32: =P32+AC32+AP32 -> 416700
A33: 8.10 | B33: ='Постоянные затраты'!A13 -> Мониторинг и аналитика | D33: ='Постоянные затраты'!B13 -> 5000 | E33: ='Постоянные затраты'!C13 -> 5000 | F33: ='Постоянные затраты'!D13 -> 5000 | G33: ='Постоянные затраты'!E13 -> 5000 | H33: ='Постоянные затраты'!F13 -> 5000 | I33: ='Постоянные затраты'!G13 -> 5000 | J33: ='Постоянные затраты'!H13 -> 5000 | K33: ='Постоянные затраты'!I13 -> 5000 | ... O33: ='Постоянные затраты'!M13 -> 5000 | P33: =SUM(D33:O33) -> 60000 | Q33: ='Постоянные затраты'!O13 -> 5750 | R33: ='Постоянные затраты'!P13 -> 5750 | S33: ='Постоянные затраты'!Q13 -> 5750 | T33: ='Постоянные затраты'!R13 -> 5750 | U33: ='Постоянные затраты'!S13 -> 5750 | V33: ='Постоянные затраты'!T13 -> 5750 | W33: ='Постоянные затраты'!U13 -> 5750 | X33: ='Постоянные затраты'!V13 -> 5750 | ... AB33: ='Постоянные затраты'!Z13 -> 5750 | AC33: =SUM(Q33:AB33) -> 69000 | AD33: ='Постоянные затраты'!AB13 -> 6612.5 | AE33: ='Постоянные затраты'!AC13 -> 6612.5 | AF33: ='Постоянные затраты'!AD13 -> 6612.5 | AG33: ='Постоянные затраты'!AE13 -> 6612.5 | AH33: ='Постоянные затраты'!AF13 -> 6612.5 | AI33: ='Постоянные затраты'!AG13 -> 6612.5 | AJ33: ='Постоянные затраты'!AH13 -> 6612.5 | AK33: ='Постоянные затраты'!AI13 -> 6612.5 | ... AO33: ='Постоянные затраты'!AM13 -> 6612.5 | AP33: =SUM(AD33:AO33) -> 79350 | AQ33: =P33+AC33+AP33 -> 208350
A34: 8.11 | B34: ='Постоянные затраты'!A14 -> Расходы 10 | D34: ='Постоянные затраты'!B14 -> 0 | E34: ='Постоянные затраты'!C14 -> 0 | F34: ='Постоянные затраты'!D14 -> 0 | G34: ='Постоянные затраты'!E14 -> 0 | H34: ='Постоянные затраты'!F14 -> 0 | I34: ='Постоянные затраты'!G14 -> 0 | J34: ='Постоянные затраты'!H14 -> 0 | K34: ='Постоянные затраты'!I14 -> 0 | ... O34: ='Постоянные затраты'!M14 -> 0 | P34: =SUM(D34:O34) -> 0 | Q34: ='Постоянные затраты'!O14 -> 0 | R34: ='Постоянные затраты'!P14 -> 0 | S34: ='Постоянные затраты'!Q14 -> 0 | T34: ='Постоянные затраты'!R14 -> 0 | U34: ='Постоянные затраты'!S14 -> 0 | V34: ='Постоянные затраты'!T14 -> 0 | W34: ='Постоянные затраты'!U14 -> 0 | X34: ='Постоянные затраты'!V14 -> 0 | ... AB34: ='Постоянные затраты'!Z14 -> 0 | AC34: =SUM(Q34:AB34) -> 0 | AD34: ='Постоянные затраты'!AB14 -> 0 | AE34: ='Постоянные затраты'!AC14 -> 0 | AF34: ='Постоянные затраты'!AD14 -> 0 | AG34: ='Постоянные затраты'!AE14 -> 0 | AH34: ='Постоянные затраты'!AF14 -> 0 | AI34: ='Постоянные затраты'!AG14 -> 0 | AJ34: ='Постоянные затраты'!AH14 -> 0 | AK34: ='Постоянные затраты'!AI14 -> 0 | ... AO34: ='Постоянные затраты'!AM14 -> 0 | AP34: =SUM(AD34:AO34) -> 0 | AQ34: =P34+AC34+AP34 -> 0
A35: 8.12 | B35: ='Постоянные затраты'!A15 -> Расходы 11 | D35: ='Постоянные затраты'!B15 -> 0 | E35: ='Постоянные затраты'!C15 -> 0 | F35: ='Постоянные затраты'!D15 -> 0 | G35: ='Постоянные затраты'!E15 -> 0 | H35: ='Постоянные затраты'!F15 -> 0 | I35: ='Постоянные затраты'!G15 -> 0 | J35: ='Постоянные затраты'!H15 -> 0 | K35: ='Постоянные затраты'!I15 -> 0 | ... O35: ='Постоянные затраты'!M15 -> 0 | P35: =SUM(D35:O35) -> 0 | Q35: ='Постоянные затраты'!O15 -> 0 | R35: ='Постоянные затраты'!P15 -> 0 | S35: ='Постоянные затраты'!Q15 -> 0 | T35: ='Постоянные затраты'!R15 -> 0 | U35: ='Постоянные затраты'!S15 -> 0 | V35: ='Постоянные затраты'!T15 -> 0 | W35: ='Постоянные затраты'!U15 -> 0 | X35: ='Постоянные затраты'!V15 -> 0 | ... AB35: ='Постоянные затраты'!Z15 -> 0 | AC35: =SUM(Q35:AB35) -> 0 | AD35: ='Постоянные затраты'!AB15 -> 0 | AE35: ='Постоянные затраты'!AC15 -> 0 | AF35: ='Постоянные затраты'!AD15 -> 0 | AG35: ='Постоянные затраты'!AE15 -> 0 | AH35: ='Постоянные затраты'!AF15 -> 0 | AI35: ='Постоянные затраты'!AG15 -> 0 | AJ35: ='Постоянные затраты'!AH15 -> 0 | AK35: ='Постоянные затраты'!AI15 -> 0 | ... AO35: ='Постоянные затраты'!AM15 -> 0 | AP35: =SUM(AD35:AO35) -> 0 | AQ35: =P35+AC35+AP35 -> 0
A36: 8.13 | B36: ='Постоянные затраты'!A16 -> Расходы 12 | D36: ='Постоянные затраты'!B16 -> 0 | E36: ='Постоянные затраты'!C16 -> 0 | F36: ='Постоянные затраты'!D16 -> 0 | G36: ='Постоянные затраты'!E16 -> 0 | H36: ='Постоянные затраты'!F16 -> 0 | I36: ='Постоянные затраты'!G16 -> 0 | J36: ='Постоянные затраты'!H16 -> 0 | K36: ='Постоянные затраты'!I16 -> 0 | ... O36: ='Постоянные затраты'!M16 -> 0 | P36: =SUM(D36:O36) -> 0 | Q36: ='Постоянные затраты'!O16 -> 0 | R36: ='Постоянные затраты'!P16 -> 0 | S36: ='Постоянные затраты'!Q16 -> 0 | T36: ='Постоянные затраты'!R16 -> 0 | U36: ='Постоянные затраты'!S16 -> 0 | V36: ='Постоянные затраты'!T16 -> 0 | W36: ='Постоянные затраты'!U16 -> 0 | X36: ='Постоянные затраты'!V16 -> 0 | ... AB36: ='Постоянные затраты'!Z16 -> 0 | AC36: =SUM(Q36:AB36) -> 0 | AD36: ='Постоянные затраты'!AB16 -> 0 | AE36: ='Постоянные затраты'!AC16 -> 0 | AF36: ='Постоянные затраты'!AD16 -> 0 | AG36: ='Постоянные затраты'!AE16 -> 0 | AH36: ='Постоянные затраты'!AF16 -> 0 | AI36: ='Постоянные затраты'!AG16 -> 0 | AJ36: ='Постоянные затраты'!AH16 -> 0 | AK36: ='Постоянные затраты'!AI16 -> 0 | ... AO36: ='Постоянные затраты'!AM16 -> 0 | AP36: =SUM(AD36:AO36) -> 0 | AQ36: =P36+AC36+AP36 -> 0
... A39: 8.16 | B39: ='Постоянные затраты'!A19 -> Расходы 15 | D39: ='Постоянные затраты'!B19 -> 0 | E39: ='Постоянные затраты'!C19 -> 0 | F39: ='Постоянные затраты'!D19 -> 0 | G39: ='Постоянные затраты'!E19 -> 0 | H39: ='Постоянные затраты'!F19 -> 0 | I39: ='Постоянные затраты'!G19 -> 0 | J39: ='Постоянные затраты'!H19 -> 0 | K39: ='Постоянные затраты'!I19 -> 0 | ... O39: ='Постоянные затраты'!M19 -> 0 | P39: =SUM(D39:O39) -> 0 | Q39: ='Постоянные затраты'!O19 -> 0 | R39: ='Постоянные затраты'!P19 -> 0 | S39: ='Постоянные затраты'!Q19 -> 0 | T39: ='Постоянные затраты'!R19 -> 0 | U39: ='Постоянные затраты'!S19 -> 0 | V39: ='Постоянные затраты'!T19 -> 0 | W39: ='Постоянные затраты'!U19 -> 0 | X39: ='Постоянные затраты'!V19 -> 0 | ... AB39: ='Постоянные затраты'!Z19 -> 0 | AC39: =SUM(Q39:AB39) -> 0 | AD39: ='Постоянные затраты'!AB19 -> 0 | AE39: ='Постоянные затраты'!AC19 -> 0 | AF39: ='Постоянные затраты'!AD19 -> 0 | AG39: ='Постоянные затраты'!AE19 -> 0 | AH39: ='Постоянные затраты'!AF19 -> 0 | AI39: ='Постоянные затраты'!AG19 -> 0 | AJ39: ='Постоянные затраты'!AH19 -> 0 | AK39: ='Постоянные затраты'!AI19 -> 0 | ... AO39: ='Постоянные затраты'!AM19 -> 0 | AP39: =SUM(AD39:AO39) -> 0 | AQ39: =P39+AC39+AP39 -> 0
A40: 8.17 | B40: Непредвиденные расходы (5%) | D40: =D6*5% -> 16200 | E40: =E6*5% -> 3950 | F40: =F6*5% -> 35450 | G40: =G6*5% -> 13200 | H40: =H6*5% -> 28200 | I40: =I6*5% -> 35700 | J40: =J6*5% -> 38200 | K40: =K6*5% -> 39550 | ... O40: =O6*5% -> 59550 | P40: =SUM(D40:O40) -> 422900 | Q40: =Q6*5% -> 94990 | R40: =R6*5% -> 117702.5 | S40: =S6*5% -> 112815 | T40: =T6*5% -> 152125.83 | U40: =U6*5% -> 132892.08 | V40: =V6*5% -> 156610.83 | W40: =W6*5% -> 153419.58 | X40: =X6*5% -> 192548.33 | ... AB40: =AB6*5% -> 231820.83 | AC40: =SUM(Q40:AB40) -> 1907217.5 | AD40: =AD6*5% -> 256763.38 | AE40: =AE6*5% -> 272104.38 | AF40: =AF6*5% -> 251605.62 | AG40: =AG6*5% -> 299744.62 | AH40: =AH6*5% -> 281428 | AI40: =AI6*5% -> 328112.25 | AJ40: =AJ6*5% -> 314027.62 | AK40: =AK6*5% -> 360844.12 | ... AO40: =AO6*5% -> 417843.88 | AP40: =SUM(AD40:AO40) -> 3881669.8 | AQ40: =P40+AC40+AP40 -> 6211787.2
A41: 9 | B41: Себестоимость без учета налога на прибыль: | D41: =D7+D9+D13+D15+D22+D23+D40 -> 897930.6 | E41: =E7+E9+E13+E15+E22+E23+E40 -> 840150.4 | F41: =F7+F9+F13+F15+F22+F23+F40 -> 976741 | G41: =G7+G9+G13+G15+G22+G23+G40 -> 869521.2 | H41: =H7+H9+H13+H15+H22+H23+H40 -> 935381.6 | I41: =I7+I9+I13+I15+I22+I23+I40 -> 959572.2 | J41: =J7+J9+J13+J15+J22+J23+J40 -> 967932.6 | K41: =K7+K9+K13+K15+K22+K23+K40 -> 985312.8 | ... O41: =O7+O9+O13+O15+O22+O23+O40 -> 1050414.8 | P41: =SUM(D41:O41) -> 11550389 | Q41: =Q7+Q9+Q13+Q15+Q22+Q23+Q40 -> 1916159.1 | R41: =R7+R9+R13+R15+R22+R23+R40 -> 2010607.8 | S41: =S7+S9+S13+S15+S22+S23+S40 -> 1975796.5 | T41: =T7+T9+T13+T15+T22+T23+T40 -> 2158518.9 | U41: =U7+U9+U13+U15+U22+U23+U40 -> 2058203.7 | V41: =V7+V9+V13+V15+V22+V23+V40 -> 2155826.3 | W41: =W7+W9+W13+W15+W22+W23+W40 -> 2126178.6 | X41: =X7+X9+X13+X15+X22+X23+X40 -> 2308061.5 | ... AB41: =AB7+AB9+AB13+AB15+AB22+AB23+AB40 -> 2454959.1 | AC41: =SUM(Q41:AB41) -> 25950906 | AD41: =AD7+AD9+AD13+AD15+AD22+AD23+AD40 -> 2834476.4 | AE41: =AE7+AE9+AE13+AE15+AE22+AE23+AE40 -> 2902849.7 | AF41: =AF7+AF9+AF13+AF15+AF22+AF23+AF40 -> 2792685.4 | AG41: =AG7+AG9+AG13+AG15+AG22+AG23+AG40 -> 3006754.1 | AH41: =AH7+AH9+AH13+AH15+AH22+AH23+AH40 -> 2912724.3 | AI41: =AI7+AI9+AI13+AI15+AI22+AI23+AI40 -> 3120555.2 | AJ41: =AJ7+AJ9+AJ13+AJ15+AJ22+AJ23+AJ40 -> 3039085.1 | AK41: =AK7+AK9+AK13+AK15+AK22+AK23+AK40 -> 3245593.5 | ... AO41: =AO7+AO9+AO13+AO15+AO22+AO23+AO40 -> 3470550.7 | AP41: =SUM(AD41:AO41) -> 37087182 | AQ41: =P41+AC41+AP41 -> 74588477
A42: 10 | B42: Итого себестоимость: | D42: =D41+D19 -> 928640.43 | E42: =E41+E19 -> 856160.23 | F42: =F41+F19 -> 1030550.8 | G42: =G41+G19 -> 896631.03 | H42: =H41+H19 -> 980491.43 | I42: =I41+I19 -> 1013682 | J42: =J41+J19 -> 1025042.4 | K42: =K41+K19 -> 1044042.6 | ... O42: =O41+O19 -> 1133144.6 | P42: =SUM(D42:O42) -> 12193107 | Q42: =Q41+Q19 -> 2066466.6 | R42: =R41+R19 -> 2188170.3 | S42: =S41+S19 -> 2147494 | T42: =T41+T19 -> 2377389.4 | U42: =U41+U19 -> 2253993.7 | V42: =V41+V19 -> 2380078.8 | W42: =W41+W19 -> 2346601.6 | X42: =X41+X19 -> 2575439 | ... AB42: =AB41+AB19 -> 2769463.6 | AC42: =SUM(Q42:AB42) -> 28675400 | AD42: =AD41+AD19 -> 3212133.1 | AE42: =AE41+AE19 -> 3298915.6 | AF42: =AF41+AF19 -> 3164152.8 | AG42: =AG41+AG19 -> 3435988.3 | AH42: =AH41+AH19 -> 3319978.6 | AI42: =AI41+AI19 -> 3583830.6 | AJ42: =AJ41+AJ19 -> 3485458.9 | AK42: =AK41+AK19 -> 3748147.1 | ... AO42: =AO41+AO19 -> 4041504.1 | AP42: =SUM(AD42:AO42) -> 42579674 | AQ42: =P42+AC42+AP42 -> 83448182
A43: 11 | B43: Рентабельность продаж | D43: =D54/D6 -> -1.8661742 | E43: =E54/E6 -> -9.8374713 | F43: =F54/F6 -> -0.45352727 | G43: =G54/G6 -> -2.3963297 | H43: =H54/H6 -> -0.73845999 | I43: =I54/I6 -> -0.41972274 | J43: =J54/J6 -> -0.34167858 | K43: =K54/K6 -> -0.31990219 | ... AQ43: =AQ54/AQ6 -> 0.32830779
A44: 12 | B44: Денежный поток от операционной деятельности | D44: =D6-D42 -> -604640.43 | E44: =E6-E42 -> -777160.23 | F44: =F6-F42 -> -321550.83 | G44: =G6-G42 -> -632631.03 | H44: =H6-H42 -> -416491.43 | I44: =I6-I42 -> -299682.03 | J44: =J6-J42 -> -261042.43 | K44: =K6-K42 -> -253042.63 | ... O44: =O6-O42 -> 57855.367 | P44: =D44+E44+F44+G44+H44+I44+J44+K44+L44+M44+N44+O44 -> -3735107.2 | Q44: =Q6-Q42 -> -166666.56 | R44: =R6-R42 -> 165879.74 | S44: =S6-S42 -> 108806.04 | T44: =T6-T42 -> 665127.27 | U44: =U6-U42 -> 403847.97 | V44: =V6-V42 -> 752137.87 | W44: =W6-W42 -> 721790.07 | X44: =X6-X42 -> 1275527.7 | ... AB44: =AB6-AB42 -> 1866953.1 | AC44: =SUM(Q44:AB44) -> 9468949.8 | AD44: =AD6-AD42 -> 1923134.4 | AE44: =AE6-AE42 -> 2143171.9 | AF44: =AF6-AF42 -> 1867959.7 | AG44: =AG6-AG42 -> 2558904.2 | AH44: =AH6-AH42 -> 2308581.4 | AI44: =AI6-AI42 -> 2978414.4 | AJ44: =AJ6-AJ42 -> 2795093.6 | AK44: =AK6-AK42 -> 3468735.4 | ... AO44: =AO6-AO42 -> 4315373.4 | AP44: =SUM(AD44:AO44) -> 35053721 | AQ44: =P44+AC44+AP44 -> 40787563
...

Sheet График чистой прибыли

Sheet План-график
B2: План-график реализации проекта
A3: № | B3: Этап проекта | C3: Начало этапа | D3: Длительность, день | E3: Конец этапа | F3: Стоимость этапа, руб.
A4: 1 | B4: Регистрация юр. лица, договоры | C4: 45658 | D4: 14 | E4: =C4+D4-1 -> 45671 | F4: 60000
A5: 2 | B5: Разработка UX/UI и брендинг | C5: =E4+1 -> 45672 | D5: 30 | E5: =C5+D5-1 -> 45701 | F5: 290000
A6: 3 | B6: Fronted + Backend (MVP) | C6: =E5+1 -> 45702 | D6: 90 | E6: =C6+D6-1 -> 45791 | F6: 900000
A7: 4 | B7: DevOps, CI/CD, инфраструктура | C7: =E6+1 -> 45792 | D7: 14 | E7: =C7+D7-1 -> 45805 | F7: 120000
A8: 5 | B8: Тестирование (QA) | C8: =E7+1 -> 45806 | D8: 21 | E8: =C8+D8-1 -> 45826 | F8: 150000
A9: 6 | B9: Запуск MVP, первые клиенты | C9: =E8+1 -> 45827 | D9: 14 | E9: =C9+D9-1 -> 45840 | F9: 100000
A10: 7 | B10: Маркетинг, привлечение (1 мес.) | C10: =E9+1 -> 45841 | D10: 31 | E10: =C10+D10-1 -> 45871 | F10: 160000
A11: 8 | B11: Поддержка, итерации, доработки | C11: =E10+1 -> 45872 | D11: 150 | E11: =C11+D11-1 -> 46021 | F11: 700000
A12: 9 | C12: =E11+1 -> 46022 | E12: =C12+D12-1 -> 46021 | F12: 0
A13: 10 | C13: =E12+1 -> 46022 | E13: =C13+D13-1 -> 46021 | F13: 0
A14: 11 | C14: =E13+1 -> 46022 | E14: =C14+D14-1 -> 46021 | F14: 0
A15: 12 | C15: =E14+1 -> 46022 | E15: =C15+D15-1 -> 46021 | F15: 0
A16: 13 | C16: =E15+1 -> 46022 | E16: =C16+D16-1 -> 46021 | F16: 0
A17: 14 | C17: =E16+1 -> 46022 | E17: =C17+D17-1 -> 46021 | F17: 0
A18: 15 | C18: =E17+1 -> 46022 | E18: =C18+D18-1 -> 46021 | F18: 0
A19: ИТОГО | D19: =SUM(D4:D18) -> 364 | E19: - | F19: =SUM(F4:F18) -> 2480000
B21: *Примечание: при отсутствии затрат на этапе запуска проекта, в графе "Стоимость этапа" оставлять пустую ячейку!!!

Sheet Диаграмма Ганта

Sheet График инвестиц.затрат

Sheet Кредит
B2: Кредитный калькулятор (аннуитетные платежи)
B4: Сумма кредита, руб.
B5: Годовая ставка | C5: 0.09
B6: Срок кредита, мес. | C6: 36
B8: Сумма ежемес. Выплат, руб. | C8: =-(PMT(C5/12,C6,C4,0,0)) -> 0
B9: Общая сумма выплат, руб. | C9: =C8*C6 -> 0
B10: Переплата, руб. | C10: =C9-C4 -> 0
A13: Период | B13: Выплата основного долга, руб. | C13: Выплата процентов, руб. | D13: Общая выплата, руб. | E13: Осталось выплатить, руб.
A14: 1 | B14: =-(PPMT($C$5/12,A14,$C$6,$C$4,0,0)) -> 0 | C14: =-(IPMT($C$5/12,A14,$C$6,$C$4,0,0)) -> 0 | D14: =B14+C14 -> 0 | E14: =C4-B14 -> 0
A15: =IF(A14>=$C$6,"",A14+1) -> 2 | B15: =-(IF(A15<>"",PPMT($C$5/12,A15,$C$6,$C$4,0,0),0)) -> 0 | C15: =-(IF(A15<>"",IPMT($C$5/12,A15,$C$6,$C$4,0,0),0)) -> 0 | D15: =IF(A15<>"",B15+C15,0) -> 0 | E15: =IF(A15<>"",$C$4-SUM($B$14:B15),0) -> 0
A16: =IF(A15>=$C$6,"",A15+1) -> 3 | B16: =-(IF(A16<>"",PPMT($C$5/12,A16,$C$6,$C$4,0,0),0)) -> 0 | C16: =-(IF(A16<>"",IPMT($C$5/12,A16,$C$6,$C$4,0,0),0)) -> 0 | D16: =IF(A16<>"",B16+C16,0) -> 0 | E16: =IF(A16<>"",$C$4-SUM($B$14:B16),0) -> 0
A17: =IF(A16>=$C$6,"",A16+1) -> 4 | B17: =-(IF(A17<>"",PPMT($C$5/12,A17,$C$6,$C$4,0,0),0)) -> 0 | C17: =-(IF(A17<>"",IPMT($C$5/12,A17,$C$6,$C$4,0,0),0)) -> 0 | D17: =IF(A17<>"",B17+C17,0) -> 0 | E17: =IF(A17<>"",$C$4-SUM($B$14:B17),0) -> 0
A18: =IF(A17>=$C$6,"",A17+1) -> 5 | B18: =-(IF(A18<>"",PPMT($C$5/12,A18,$C$6,$C$4,0,0),0)) -> 0 | C18: =-(IF(A18<>"",IPMT($C$5/12,A18,$C$6,$C$4,0,0),0)) -> 0 | D18: =IF(A18<>"",B18+C18,0) -> 0 | E18: =IF(A18<>"",$C$4-SUM($B$14:B18),0) -> 0
A19: =IF(A18>=$C$6,"",A18+1) -> 6 | B19: =-(IF(A19<>"",PPMT($C$5/12,A19,$C$6,$C$4,0,0),0)) -> 0 | C19: =-(IF(A19<>"",IPMT($C$5/12,A19,$C$6,$C$4,0,0),0)) -> 0 | D19: =IF(A19<>"",B19+C19,0) -> 0 | E19: =IF(A19<>"",$C$4-SUM($B$14:B19),0) -> 0
A20: =IF(A19>=$C$6,"",A19+1) -> 7 | B20: =-(IF(A20<>"",PPMT($C$5/12,A20,$C$6,$C$4,0,0),0)) -> 0 | C20: =-(IF(A20<>"",IPMT($C$5/12,A20,$C$6,$C$4,0,0),0)) -> 0 | D20: =IF(A20<>"",B20+C20,0) -> 0 | E20: =IF(A20<>"",$C$4-SUM($B$14:B20),0) -> 0
A21: =IF(A20>=$C$6,"",A20+1) -> 8 | B21: =-(IF(A21<>"",PPMT($C$5/12,A21,$C$6,$C$4,0,0),0)) -> 0 | C21: =-(IF(A21<>"",IPMT($C$5/12,A21,$C$6,$C$4,0,0),0)) -> 0 | D21: =IF(A21<>"",B21+C21,0) -> 0 | E21: =IF(A21<>"",$C$4-SUM($B$14:B21),0) -> 0
A22: =IF(A21>=$C$6,"",A21+1) -> 9 | B22: =-(IF(A22<>"",PPMT($C$5/12,A22,$C$6,$C$4,0,0),0)) -> 0 | C22: =-(IF(A22<>"",IPMT($C$5/12,A22,$C$6,$C$4,0,0),0)) -> 0 | D22: =IF(A22<>"",B22+C22,0) -> 0 | E22: =IF(A22<>"",$C$4-SUM($B$14:B22),0) -> 0
A23: =IF(A22>=$C$6,"",A22+1) -> 10 | B23: =-(IF(A23<>"",PPMT($C$5/12,A23,$C$6,$C$4,0,0),0)) -> 0 | C23: =-(IF(A23<>"",IPMT($C$5/12,A23,$C$6,$C$4,0,0),0)) -> 0 | D23: =IF(A23<>"",B23+C23,0) -> 0 | E23: =IF(A23<>"",$C$4-SUM($B$14:B23),0) -> 0
A24: =IF(A23>=$C$6,"",A23+1) -> 11 | B24: =-(IF(A24<>"",PPMT($C$5/12,A24,$C$6,$C$4,0,0),0)) -> 0 | C24: =-(IF(A24<>"",IPMT($C$5/12,A24,$C$6,$C$4,0,0),0)) -> 0 | D24: =IF(A24<>"",B24+C24,0) -> 0 | E24: =IF(A24<>"",$C$4-SUM($B$14:B24),0) -> 0
A25: =IF(A24>=$C$6,"",A24+1) -> 12 | B25: =-(IF(A25<>"",PPMT($C$5/12,A25,$C$6,$C$4,0,0),0)) -> 0 | C25: =-(IF(A25<>"",IPMT($C$5/12,A25,$C$6,$C$4,0,0),0)) -> 0 | D25: =IF(A25<>"",B25+C25,0) -> 0 | E25: =IF(A25<>"",$C$4-SUM($B$14:B25),0) -> 0
A26: =IF(A25>=$C$6,"",A25+1) -> 13 | B26: =-(IF(A26<>"",PPMT($C$5/12,A26,$C$6,$C$4,0,0),0)) -> 0 | C26: =-(IF(A26<>"",IPMT($C$5/12,A26,$C$6,$C$4,0,0),0)) -> 0 | D26: =IF(A26<>"",B26+C26,0) -> 0 | E26: =IF(A26<>"",$C$4-SUM($B$14:B26),0) -> 0
... A50: =IF(A49>=$C$6,"",A49+1) | B50: =-(IF(A50<>"",PPMT($C$5/12,A50,$C$6,$C$4,0,0),0)) -> 0 | C50: =-(IF(A50<>"",IPMT($C$5/12,A50,$C$6,$C$4,0,0),0)) -> 0 | D50: =IF(A50<>"",B50+C50,0) -> 0 | E50: =IF(A50<>"",$C$4-SUM($B$14:B50),0) -> 0

Sheet Продукция и цена 
A2: Цены реализации
A3: Наименование продукта/услуги | B3: Ед. изм | C3: Цена, руб. | D3: Цена, руб. | E3: Цена, руб.
A4: Аренда системы: "Базовый" тариф | B4: мес/объект | C4: 35000 | D4: =C4+C4*'Вводные данные'!$D$4 -> 40250 | E4: =D4+D4*'Вводные данные'!$E$4 -> 46287.5
A5: Поддержка системы | B5: мес/объект | C5: 15000 | D5: =C5+C5*'Вводные данные'!$D$4 -> 17250 | E5: =D5+D5*'Вводные данные'!$E$4 -> 19837.5
A6: Встроенная коммерция (доп. услуги) | B6: мес/услуга | C6: 9000 | D6: =C6+C6*'Вводные данные'!$D$4 -> 10350 | E6: =D6+D6*'Вводные данные'!$E$4 -> 11902.5
A7: Установка и настройка системы, онбординг | B7: разово | C7: 250000 | D7: =C7+C7*'Вводные данные'!$D$4 -> 287500 | E7: =D7+D7*'Вводные данные'!$E$4 -> 330625
A8: Реклама/партнёрства | B8: руб/мес | C8: 20000 | D8: =C8+C8*'Вводные данные'!$D$4 -> 23000 | E8: =D8+D8*'Вводные данные'!$E$4 -> 26450
D9: =C9+C9*'Вводные данные'!$D$4 -> 0 | E9: =D9+D9*'Вводные данные'!$E$4 -> 0
D10: =C10+C10*'Вводные данные'!$D$4 -> 0 | E10: =D10+D10*'Вводные данные'!$E$4 -> 0
A11: Аренда системы: "Продвинутый" тариф | B11: мес/объект | C11: 65000 | D11: =C11+C11*'Вводные данные'!$D$4 -> 74750 | E11: =D11+D11*'Вводные данные'!$E$4 -> 85962.5
A12: Аренда системы: "Бизнес" тариф | B12: мес/объект | C12: 12000 | D12: =C12+C12*'Вводные данные'!$D$4 -> 13800 | E12: =D12+D12*'Вводные данные'!$E$4 -> 15870
D13: =C13+C13*'Вводные данные'!$D$4 -> 0 | E13: =D13+D13*'Вводные данные'!$E$4 -> 0

Sheet Продажи
A2: Объем производства в натуральном выражении (шт, чел, тонн и пр.)
A3: Наименование продукта/услуги | B3: 1 год | N3: ИТОГО за 1 год | O3: 2 год | AA3: ИТОГО за 2 год | AB3: 3 год | AN3: ИТОГО за 3 год
B4: =РДДС!D5 -> 45809 | C4: =РДДС!E5 -> 45839 | D4: =РДДС!F5 -> 45870 | E4: =РДДС!G5 -> 45901 | F4: =РДДС!H5 -> 45931 | G4: =РДДС!I5 -> 45962 | H4: =РДДС!J5 -> 45992 | I4: =РДДС!K5 -> 46023 | ... M4: =РДДС!O5 -> 46143 | O4: =РДДС!Q5 -> 46174 | P4: =РДДС!R5 -> 46204 | Q4: =РДДС!S5 -> 46235 | R4: =РДДС!T5 -> 46266 | S4: =РДДС!U5 -> 46296 | T4: =РДДС!V5 -> 46327 | U4: =РДДС!W5 -> 46357 | V4: =РДДС!X5 -> 46388 | ... Z4: =РДДС!AB5 -> 46508 | AB4: =РДДС!AD5 -> 46539 | AC4: =РДДС!AE5 -> 46569 | AD4: =РДДС!AF5 -> 46600 | AE4: =РДДС!AG5 -> 46631 | AF4: =РДДС!AH5 -> 46661 | AG4: =РДДС!AI5 -> 46692 | AH4: =РДДС!AJ5 -> 46722 | AI4: =РДДС!AK5 -> 46753 | ... AM4: =РДДС!AO5 -> 46874
A5: ='Продукция и цена '!A4 -> Аренда системы: "Базовый" тариф | B5: 1 | C5: 2 | D5: 3 | E5: 4 | F5: 5 | G5: 7 | H5: 8 | I5: 8 | J5: 10 | K5: 12 | L5: 13 | M5: 14 | N5: =SUM(B5:M5) -> 87 | O5: 15 | P5: 16 | Q5: 18 | R5: 19.333333 | S5: 20.833333 | T5: 22.333333 | U5: 23.833333 | V5: 25.333333 | W5: 26.833333 | X5: 28.333333 | Y5: 29.833333 | Z5: 31.333333 | AA5: =SUM(O5:Z5) -> 277 | AB5: 6 | AC5: 6 | AD5: 6 | AE5: 6 | AF5: 6 | AG5: 6 | AH5: 7 | AI5: 7 | AJ5: 7 | AK5: 7 | AL5: 7 | AM5: 7 | AN5: =SUM(AB5:AM5) -> 78
A6: ='Продукция и цена '!A5 -> Поддержка системы | B6: 2 | C6: 0 | D6: 2 | E6: 2 | F6: 3 | G6: 4 | H6: 5 | I6: 6 | J6: 8 | K6: 8 | L6: 9 | M6: 10 | N6: =SUM(B6:M6) -> 59 | O6: 12 | P6: 15 | Q6: 17 | R6: 21 | S6: 23 | T6: 26 | U6: 28 | V6: 32 | W6: 34 | X6: 37 | Y6: 39 | Z6: 43 | AA6: =SUM(O6:Z6) -> 327 | AB6: 49 | AC6: 55 | AD6: 59 | AE6: 65 | AF6: 69 | AG6: 75 | AH6: 79 | AI6: 85 | AJ6: 89 | AK6: 95 | AL6: 99 | AM6: 105 | AN6: =SUM(AB6:AM6) -> 924
A7: ='Продукция и цена '!A6 -> Встроенная коммерция (доп. услуги) | B7: 1 | C7: 1 | D7: 1 | E7: 1 | F7: 1 | G7: 1 | H7: 1 | I7: 1 | J7: 1 | K7: 1 | L7: 1 | M7: 1 | N7: =SUM(B7:M7) -> 12 | O7: 10 | P7: 10 | Q7: 10 | R7: 10 | S7: 12 | T7: 12 | U7: 15 | V7: 14 | W7: 18 | X7: 18 | Y7: 18 | Z7: 18 | AA7: =SUM(O7:Z7) -> 165 | AB7: 20 | AC7: 20 | AD7: 20 | AE7: 20 | AF7: 23 | AG7: 23 | AH7: 27 | AI7: 25 | AJ7: 26 | AK7: 26 | AL7: 27 | AM7: 27 | AN7: =SUM(AB7:AM7) -> 284
A8: ='Продукция и цена '!A7 -> Установка и настройка системы, онбординг | B8: 1 | C8: 0 | D8: 2 | E8: 0 | F8: 1 | G8: 1 | H8: 1 | I8: 1 | J8: 2 | K8: 0 | L8: 1 | M8: 1 | N8: =SUM(B8:M8) -> 11 | O8: 2 | P8: 3 | Q8: 2 | R8: 4 | S8: 2 | T8: 3 | U8: 2 | V8: 4 | W8: 2 | X8: 3 | Y8: 2 | Z8: 4 | AA8: =SUM(O8:Z8) -> 33 | AB8: 6 | AC8: 6 | AD8: 4 | AE8: 6 | AF8: 4 | AG8: 6 | AH8: 4 | AI8: 6 | AJ8: 4 | AK8: 6 | AL8: 4 | AM8: 6 | AN8: =SUM(AB8:AM8) -> 62
A9: ='Продукция и цена '!A8 -> Реклама/партнёрства | B9: 0 | C9: 0 | D9: 0 | E9: 1 | F9: 1 | G9: 1 | H9: 1 | I9: 1 | J9: 1 | K9: 1 | L9: 1 | M9: 1 | N9: =SUM(B9:M9) -> 9 | O9: 1 | P9: 1 | Q9: 1 | R9: 1 | S9: 1 | T9: 1 | U9: 2 | V9: 2 | W9: 1 | X9: 1 | Y9: 2 | Z9: 2 | AA9: =SUM(O9:Z9) -> 16 | AB9: 2 | AC9: 2 | AD9: 2 | AE9: 2 | AF9: 2 | AG9: 1 | AH9: 2 | AI9: 2 | AJ9: 2 | AK9: 1 | AL9: 2 | AM9: 2 | AN9: =SUM(AB9:AM9) -> 22
A10: ='Продукция и цена '!A9 -> 0 | B10: 0 | C10: 0 | D10: 0 | E10: 0 | F10: 0 | G10: 0 | H10: 0 | I10: 0 | J10: 0 | K10: 0 | L10: 0 | M10: 0 | N10: =SUM(B10:M10) -> 0 | O10: 0 | P10: 0 | Q10: 0 | R10: 0 | S10: 0 | T10: 0 | U10: 0 | V10: 0 | W10: 3 | X10: 3 | Y10: 0 | Z10: 0 | AA10: =SUM(O10:Z10) -> 6 | AB10: 0 | AC10: 0 | AD10: 0 | AE10: 0 | AF10: 0 | AG10: 0 | AH10: 0 | AI10: 0 | AJ10: 0 | AK10: 0 | AL10: 0 | AM10: 0 | AN10: =SUM(AB10:AM10) -> 0
A11: ='Продукция и цена '!A10 -> 0 | B11: 0 | C11: 0 | D11: 0 | E11: 0 | F11: 0 | G11: 0 | H11: 0 | I11: 0 | J11: 0 | K11: 0 | L11: 0 | M11: 0 | N11: =SUM(B11:M11) -> 0 | O11: 0 | P11: 0 | Q11: 0 | R11: 0 | S11: 0 | T11: 0 | U11: 0 | V11: 0 | W11: 0 | X11: 0 | Y11: 0 | Z11: 0 | AA11: =SUM(O11:Z11) -> 0 | AB11: 0 | AC11: 0 | AD11: 0 | AE11: 0 | AF11: 0 | AG11: 0 | AH11: 0 | AI11: 0 | AJ11: 0 | AK11: 0 | AL11: 0 | AM11: 0 | AN11: =SUM(AB11:AM11) -> 0
A12: ='Продукция и цена '!A11 -> Аренда системы: "Продвинутый" тариф | B12: 0 | C12: 0 | D12: 1 | E12: 1 | F12: 1 | G12: 2 | H12: 2 | I12: 2 | J12: 3 | K12: 3 | L12: 3 | M12: 4 | N12: =SUM(B12:M12) -> 22 | O12: 5 | P12: 6 | Q12: 7 | R12: 8 | S12: 9 | T12: 10 | U12: 11 | V12: 12 | W12: 13 | X12: 14 | Y12: 15 | Z12: 16 | AA12: =SUM(O12:Z12) -> 126 | AB12: 18 | AC12: 20 | AD12: 22 | AE12: 24 | AF12: 26 | AG12: 28 | AH12: 30 | AI12: 32 | AJ12: 34 | AK12: 36 | AL12: 38 | AM12: 40 | AN12: =SUM(AB12:AM12) -> 348
A13: ='Продукция и цена '!A12 -> Аренда системы: "Бизнес" тариф | B13: 0 | C13: 0 | D13: 0 | E13: 0 | F13: 0 | G13: 0 | H13: 0 | I13: 1 | J13: 1 | K13: 1 | L13: 1 | M13: 1 | N13: =SUM(B13:M13) -> 5 | O13: 1 | P13: 1 | Q13: 1 | R13: 2 | S13: 2 | T13: 2 | U13: 2 | V13: 3 | W13: 3 | X13: 3 | Y13: 3 | Z13: 4 | AA13: =SUM(O13:Z13) -> 27 | AB13: 4 | AC13: 5 | AD13: 5 | AE13: 5.6666667 | AF13: 6.1666667 | AG13: 6.6666667 | AH13: 7.1666667 | AI13: 7.6666667 | AJ13: 8.1666667 | AK13: 8.6666667 | AL13: 9.1666667 | AM13: 9.6666667 | AN13: =SUM(AB13:AM13) -> 83
A14: ='Продукция и цена '!A13 -> 0 | N14: =SUM(B14:M14) -> 0 | AA14: =SUM(O14:Z14) -> 0 | AN14: =SUM(AB14:AM14) -> 0
A15: ИТОГО | B15: =SUM(B5:B14) -> 5 | C15: =SUM(C5:C14) -> 3 | D15: =SUM(D5:D14) -> 9 | E15: =SUM(E5:E14) -> 9 | F15: =SUM(F5:F14) -> 12 | G15: =SUM(G5:G14) -> 16 | H15: =SUM(H5:H14) -> 18 | I15: =SUM(I5:I14) -> 20 | ... M15: =SUM(M5:M14) -> 32 | N15: =SUM(B15:M15) -> 205 | O15: =SUM(O5:O14) -> 46 | P15: =SUM(P5:P14) -> 52 | Q15: =SUM(Q5:Q14) -> 56 | R15: =SUM(R5:R14) -> 65.333333 | S15: =SUM(S5:S14) -> 69.833333 | T15: =SUM(T5:T14) -> 76.333333 | U15: =SUM(U5:U14) -> 83.833333 | V15: =SUM(V5:V14) -> 92.333333 | ... Z15: =SUM(Z5:Z14) -> 118.33333 | AA15: =SUM(O15:Z15) -> 977 | AB15: =SUM(AB5:AB14) -> 105 | AC15: =SUM(AC5:AC14) -> 114 | AD15: =SUM(AD5:AD14) -> 118 | AE15: =SUM(AE5:AE14) -> 128.66667 | AF15: =SUM(AF5:AF14) -> 136.16667 | AG15: =SUM(AG5:AG14) -> 145.66667 | AH15: =SUM(AH5:AH14) -> 156.16667 | AI15: =SUM(AI5:AI14) -> 164.66667 | ... AM15: =SUM(AM5:AM14) -> 196.66667 | AN15: =SUM(AB15:AM15) -> 1801
A18: Прогноз выручки (с учетом % потерь при сбыте), руб.
A19: Наименование продукта/услуги | B19: 1 год | N19: ИТОГО за 1 год | O19: =O3 -> 2 год | AA19: =AA3 -> ИТОГО за 2 год | AB19: =AB3 -> 3 год | AN19: =AN3 -> ИТОГО за 3 год
B20: =B4 -> 45809 | C20: =C4 -> 45839 | D20: =D4 -> 45870 | E20: =E4 -> 45901 | F20: =F4 -> 45931 | G20: =G4 -> 45962 | H20: =H4 -> 45992 | I20: =I4 -> 46023 | ... M20: =M4 -> 46143 | O20: =O4 -> 46174 | P20: =P4 -> 46204 | Q20: =Q4 -> 46235 | R20: =R4 -> 46266 | S20: =S4 -> 46296 | T20: =T4 -> 46327 | U20: =U4 -> 46357 | V20: =V4 -> 46388 | ... Z20: =Z4 -> 46508 | AB20: =AB4 -> 46539 | AC20: =AC4 -> 46569 | AD20: =AD4 -> 46600 | AE20: =AE4 -> 46631 | AF20: =AF4 -> 46661 | AG20: =AG4 -> 46692 | AH20: =AH4 -> 46722 | AI20: =AI4 -> 46753 | ... AM20: =AM4 -> 46874
